Traceback (most recent call last):
  File "/home/travis/virtualenv/python3.7.1/lib/python3.7/site-packages/jupyter_cache/executors/utils.py", line 56, in single_nb_execution
    record_timing=False,
  File "/home/travis/virtualenv/python3.7.1/lib/python3.7/site-packages/nbclient/client.py", line 1117, in execute
    return NotebookClient(nb=nb, resources=resources, km=km, **kwargs).execute()
  File "/home/travis/virtualenv/python3.7.1/lib/python3.7/site-packages/nbclient/util.py", line 78, in wrapped
    return just_run(coro(*args, **kwargs))
  File "/home/travis/virtualenv/python3.7.1/lib/python3.7/site-packages/nbclient/util.py", line 57, in just_run
    return loop.run_until_complete(coro)
  File "/opt/python/3.7.1/lib/python3.7/asyncio/base_events.py", line 573, in run_until_complete
    return future.result()
  File "/home/travis/virtualenv/python3.7.1/lib/python3.7/site-packages/nbclient/client.py", line 559, in async_execute
    cell, index, execution_count=self.code_cells_executed + 1
  File "/home/travis/virtualenv/python3.7.1/lib/python3.7/site-packages/nbclient/client.py", line 862, in async_execute_cell
    self._check_raise_for_error(cell, exec_reply)
  File "/home/travis/virtualenv/python3.7.1/lib/python3.7/site-packages/nbclient/client.py", line 765, in _check_raise_for_error
    raise CellExecutionError.from_cell_and_msg(cell, exec_reply_content)
nbclient.exceptions.CellExecutionError: An error occurred while executing the following cell:
------------------
from rpy2.robjects import pandas2ri
%load_ext rpy2.ipython
pandas2ri.activate()
------------------

[0;31m---------------------------------------------------------------------------[0m
[0;31mModuleNotFoundError[0m                       Traceback (most recent call last)
[0;32m/tmp/ipykernel_5896/3198097203.py[0m in [0;36m<module>[0;34m[0m
[0;32m----> 1[0;31m [0;32mfrom[0m [0mrpy2[0m[0;34m.[0m[0mrobjects[0m [0;32mimport[0m [0mpandas2ri[0m[0;34m[0m[0;34m[0m[0m
[0m[1;32m      2[0m [0mget_ipython[0m[0;34m([0m[0;34m)[0m[0;34m.[0m[0mrun_line_magic[0m[0;34m([0m[0;34m'load_ext'[0m[0;34m,[0m [0;34m'rpy2.ipython'[0m[0;34m)[0m[0;34m[0m[0;34m[0m[0m
[1;32m      3[0m [0mpandas2ri[0m[0;34m.[0m[0mactivate[0m[0;34m([0m[0;34m)[0m[0;34m[0m[0;34m[0m[0m

[0;31mModuleNotFoundError[0m: No module named 'rpy2'
ModuleNotFoundError: No module named 'rpy2'

